Workbook

Sheet Sommaire
B3: Fonct. | C3: A.Q | D3: Total | E3: Heures de retard (-10%)/heure | F3: Poids | G3: Note pondérée | H3: Documents
A4: Sprint 1 | B4: =(Fonctionnalités!E14) -> 0.534375 | C4: ='Assurance Qualité'!C59 -> 0.67 | D4: =B4*0.6+C4*0.4 - 0.1*E4 -> 0.588625 | F4: 20 | G4: =D4*F4 -> 11.7725 | H4: =Documents!B16*5 -> 3.35625
A5: Sprint 2 | B5: =(Fonctionnalités!E25) -> 0.82 | C5: ='Assurance Qualité'!F59 -> 0.736 | D5: =B5*0.6+C5*0.4 - 0.1*E5 -> 0.7864 | F5: 20 | G5: =D5*F5 -> 15.728 | H5: =Documents!E16*5 -> 2.85
A6: Sprint 3 | B6: =(Fonctionnalités!E38) -> 0.965 | C6: ='Assurance Qualité'!I59 -> 0.7975 | D6: =B6*0.6+C6*0.4 - 0.1*E6 -> 0.898 | F6: 20 | G6: =D6*F6 -> 17.96
A7: UX | D7: 0.7 | F7: 5 | G7: =D7*F7 -> 3.5

Sheet Assurance Qualité
A2: Grille de correction LOG2990
A4: Assurance Qualité
A6: Critère | B6: Description | C6: Sprint 1 | F6: Sprint 2 | I6: Sprint 3
C7: Note | D7: Poids | E7: Commentaires | F7: Note | G7: Poids | H7: Commentaires | I7: Note | J7: Poids | K7: Commentaires
A8: 1. Projet | C8: Correcteur | E8: Marc-Olivier | F8: Correcteur | H8: Marc-Olivier | I8: Correcteur | K8: Marc-Olivier
A9: 1.1 Utilisation des Cadriciels | B9: Le projet respecte les meilleures pratiques des cadriciels utilisés. (Exemple: séparation des responsabilités dans les Components et Services d'Angular, respect de la sémantique HTTP avec Express, etc.) | C9: 0 | D9: 6 | E9: Vous ne devriez pas utiliser document. modifyGameVisibility :isVisible inutile Vous ne devriez pas mettre de balise <html> dans vos component | F9: 0.5 | G9: 6 | H9: Vous ne devriez pas utiliser document. | I9: 0.25 | J9: 6 | K9: Vous ne respectez pas la séparation des responsabilités (patron MVC). ORganiserPageComponet et PlayAreaComponent font beaucoup de chose qui aurait du être délégué a un service
A10: 1.2 Arborescence | B10: Le projet respecte une arborescence de fichier claire,uniforme et structurée. Les noms de fichiers et dossiers respectent le format kebab-case. | C10: 1 | D10: 2 | E10: Bon travail! | F10: 1 | G10: 2 | H10: Bon travail! | I10: 1 | J10: 2 | K10: Bon travail!
A11: Sous-total | C11: =SUMPRODUCT(C6:C10,D6:D10) -> 2 | D11: =SUM(D6:D10) -> 8 | F11: =SUMPRODUCT(F6:F10,G6:G10) -> 5 | G11: =SUM(G6:G10) -> 8 | I11: =SUMPRODUCT(I6:I10,J6:J10) -> 3.5 | J11: =SUM(J6:J10) -> 8
A12: 2. Classe | C12: Correcteur | E12: Marc-Olivier | F12: Correcteur | H12: Marc-Olivier | I12: Correcteur | K12: Marc-Olivier
A13: 2.1 Responsabilité | B13: La classe n'a qu'une responsabilitée. | C13: 1 | D13: 3 | E13: Bon travail! | F13: 0 | G13: =D13 -> 3 | H13: PlayAreaComponent trop de responsabilités PlayGateway trop de responsabilités | I13: 0 | J13: =G13 -> 3 | K13: Même problème
A14: 2.2 Attributs | B14: La classe comporte uniquement des attributs utilisés. La classe comporte uniquement des attributs qui sont des états de la classe. La classe ne comporte pas d'attribut utilisé seulement dans les tests. | C14: 1 | D14: 2 | E14: Bon travail! | F14: 1 | G14: =D14 -> 2 | H14: Bon travail! | I14: 1 | J14: =G14 -> 2 | K14: Bon travail
A15: 2.3 Accessibilité | B15: La classe minimise l'accessibilité des membres. (Bonne utilisation de public/private/protected pour les attributs et les fonctions) Les méthodes get/set font une validation quelconque sur les attributs privés. | C15: 0 | D15: 2 | E15: Aucune gestion | F15: 0 | G15: =D15 -> 2 | H15: Aucune gestion | I15: 0 | J15: =G15 -> 2 | K15: Aucune gestion
A16: 2.4 Couplage | B16: La classe minimise le couplage aux autres classes. La classe minimise les longues chaînes d'appels (ex : foo.bar.baz.foo) | C16: 1 | D16: 4 | E16: Bon travail! | F16: 1 | G16: =D16 -> 4 | H16: Bon travail! | I16: 0.5 | J16: =G16 -> 4 | K16: OrganiserPageComponent beaucoup trop de couplage
A17: 2.5 Valeur par défaut | B17: La classe initialise tous ses attributs de la même façon. Soit à la définition, soit dans le constructeur. | C17: 1 | D17: 4 | E17: Bon travail! | F17: 1 | G17: =D17 -> 4 | H17: Bon travail! | I17: 1 | J17: =G17 -> 4 | K17: Bon travail
A18: Sous-total | C18: =SUMPRODUCT(C13:C17,D13:D17) -> 13 | D18: =SUM(D13:D17) -> 15 | F18: =SUMPRODUCT(F13:F17,G13:G17) -> 10 | G18: =SUM(G13:G17) -> 15 | I18: =SUMPRODUCT(I13:I17,J13:J17) -> 8 | J18: =SUM(J13:J17) -> 15
A19: 3. Fonctions et méthodes | C19: Correcteur | E19: Marc-Olivier | F19: Correcteur | H19: Marc-Olivier | I19: Correcteur | K19: Marc-Olivier
A20: 3.1 Utilité | B20: La fonction est utilie et non-triviale. La fonction ne peut pas être fragmenté en plusieurs fonctions. La fonction n'a pas une longueur trop grande. | C20: 1 | D20: 3 | E20: Bon travail! | F20: 0.5 | G20: 3 | H20: submitGame, validateQuestion trop complexe | I20: 0.75 | J20: 3 | K20: sendTimer trop de param
A21: 3.2 Paramètres | B21: La fonction possède le moins de paramètres possibles en entrée. La fonction possède uniquement des paramètres d'entrée qui sont utilisés. | C21: 0.75 | D21: 3 | E21: submitGame(_newGame) | F21: 1 | G21: 3 | H21: Bon travail! | I21: 1 | J21: 3 | K21: Bon travail!
A22: Sous-total | C22: =SUMPRODUCT(C20:C21,D20:D21) -> 5.25 | D22: =SUM(D20:D21) -> 6 | F22: =SUMPRODUCT(F20:F21,G20:G21) -> 4.5 | G22: =SUM(G20:G21) -> 6 | I22: =SUMPRODUCT(I20:I21,J20:J21) -> 5.25 | J22: =SUM(J20:J21) -> 6
A23: 4. Gestion des ressources et erreurs | C23: Correcteur | E23: Augustin | F23: Correcteur | H23: Augustin | I23: Correcteur | K23: Augustin
A24: 4.1 Console | B24: La console ne génère pas de message d'avertissement (warning) ou d'erreur (error) qui aurait pu être gérés par le programme. | C24: 1 | D24: 1 | F24: 1 | G24: 1 | I24: 1 | J24: 1
A25: 4.2 Code asynchrone | B25: Le code asynchrone (Promise, Observable, Event) est géré adéquatement. | C25: 0 | D25: 2 | E25: Les fonctions faisant des appels réseaux ou leur parents devraient être asynchrones. Les parents devraient s'assurer d'attendre la résolution des appels réseaux | F25: 0 | G25: 2 | H25: Les fonctions faisant des appels réseaux ou leur parents devraient être asynchrones. Les parents devraient s'assurer d'attendre la résolution des appels réseaux | I25: 0 | J25: 2 | K25: Les fonctions faisant des appels réseaux ou leur parents devraient être asynchrones. Les parents devraient s'assurer d'attendre la résolution des appels réseaux
A26: 4.3 Message d'erreur | B26: Le message d'erreur est précis et compréhensible par l'utilisateur moyen. | C26: 1 | D26: 1 | F26: 1 | G26: 1 | I26: 1 | J26: 1
A27: Sous-total | C27: =SUMPRODUCT(C24:C26,D24:D26) -> 2 | D27: =SUM(D24:D26) -> 4 | F27: =SUMPRODUCT(F24:F26,G24:G26) -> 2 | G27: =SUM(G24:G26) -> 4 | I27: =SUMPRODUCT(I24:I26,J24:J26) -> 2 | J27: =SUM(J24:J26) -> 4
A28: 5. Variables et constantes | C28: Correcteur | E28: Antonin | F28: Correcteur | H28: Antonin | I28: Correcteur | K28: Antonin
A29: 5.1 Groupement | B29: Les constantes sont regroupées ensemble en groupes logiques. | C29: 0.75 | D29: 2 | E29: -0.25 9,1: const MAX_NUMBER_OF_CHOICES = 4; -0.25 10,1: const INITIAL_VALUE_SLIDER = 10; -0.25 6,1: const MIN_NUMBER_OF_CHOICES = 2; | F29: 1 | G29: =D29 -> 2 | I29: 1 | J29: =D29 -> 2
A30: 5.2 Environnement | B30: Des variables d'environnements sont utilisées lorsque possible. | C30: 1 | D30: 2 | F30: 1 | G30: =D30 -> 2 | I30: 1 | J30: =D30 -> 2
A31: 5.3 Contexte d'utilisation | B31: La constante est utilisé dans un contexte lié à la logique d'affaire. (Exemple d'erreur: const DEUX = 2, bonne utilisation: WAIT_TIME = 5000 ) | C31: 0.75 | D31: 2 | E31: -0.25 74,13:const a = document.createElement('a'); | F31: 1 | G31: =D31 -> 2 | I31: 1 | J31: =D31 -> 2
A32: Sous-total | C32: =SUMPRODUCT(C29:C31,D29:D31) -> 5 | D32: =SUM(D29:D31) -> 6 | F32: =SUMPRODUCT(F29:F31,G29:G31) -> 6 | G32: =SUM(G29:G31) -> 6 | I32: =SUMPRODUCT(I29:I31,J29:J31) -> 6 | J32: =SUM(J29:J31) -> 6
A33: 6. Expressions booléennes | C33: Correcteur | E33: Augustin | F33: Correcteur | H33: Augustin | I33: Correcteur | K33: Augustin
A34: 6.1 Expression | B34: L'expression booléenne n'est pas comparée à true ou false. (Exemple d'erreur: x === true) | C34: 0 | D34: 2 | E34: client/src/app/components/play-area/play-area.component.ts L67 client/src/app/services/qcm-validation-service/qcm-validation.service.ts L16 | F34: 1 | G34: 2 | I34: 1 | J34: 2
A35: 6.2 Logique négative | B35: L'expression booléenne évite la logique négative. (Exemple d'erreur: if( !notFound(…) ) | C35: 1 | D35: 2 | F35: 1 | G35: 2 | I35: 1 | J35: 2
A36: 6.3 Ternaire | B36: L'expression booléenne utilise un ternaire dans le bon scénario. | C36: 0.25 | D36: 3 | E36: client/src/app/components/play-area/play-area.component.ts L78 - 82 | F36: 0.25 | G36: 3 | H36: client/src/app/components/play-area/play-area.component.ts L208 client/src/app/pages/test-game-page/test-game-page.component.ts L74 | I36: 1 | J36: 3
A37: 6.4 Prédicats | B37: L'expression booléenne est simple. L'expression booléenne utilise un ou des prédicats pour simplifier une condition complexe. | C37: 1 | D37: 3 | F37: 0.25 | G37: 3 | H37: client/src/app/pages/create-game-page/create-game-page.component.ts L96 else inutile client/src/app/services/keyboard-service/keyboard.service.ts L34 | I37: 1 | J37: 3
A38: Sous-total | C38: =SUMPRODUCT(C34:C37,D34:D37) -> 5.75 | D38: =SUM(D34:D37) -> 10 | F38: =SUMPRODUCT(F34:F37,G34:G37) -> 5.5 | G38: =SUM(G34:G37) -> 10 | I38: =SUMPRODUCT(I34:I37,J34:J37) -> 10 | J38: =SUM(J34:J37) -> 10
A39: 7. Qualité générale | C39: Correcteur | E39: Karim | F39: Correcteur | H39: Karim | I39: Correcteur | K39: Karim
A40: 7.1 Langue | B40: La langue utilisée pour les variables, classes et fonctions est uniforme pour tout le code source. La langue utilisée pour les commentaires doit être uniforme, mais peut être différente que la langue du code source. | C40: 1 | D40: 2 | E40: Bravo! | F40: 1 | G40: =D40 -> 2 | H40: Bon travail! | I40: 1 | J40: =D40 -> 2 | K40: Bravo!
A41: 7.2 Commentaire | B41: Le commentaire est pertinent. (Pas de code mort commenté) | C41: 0 | D41: 2 | E41: Plusieurs services et controlleurs commentés: LOG2990-209/server/app/controllers/password/password.controller.ts LOG2990-209/server/app/controllers/game/game.controller.ts LOG2990-209/server/app/services/game/game.service.ts LOG2990-209/server/app/services/password/password.service.ts | F41: 0 | G41: =D41 -> 2 | H41: server\app\services\password\password.service.ts 44,5: // async addPassword(password: CreatePasswordDto): Promise<void> { 45,5: // await this.passwordModel.create(password); 46,5: // } 48,5: // async modifyPassword(password: UpdatePasswordDto): Promise<void> { 49,5: // const filterQuery = { password: password.password }; 50,5: // try { 51,5: // const res = await this.passwordModel.updateOne(filterQuery, password); 52,5: // if (res.matchedCount === 0) { 53,5: // return Promise.reject('Could not find password'); 54,5: // } 55,5: // } catch (error) { 56,5: // return Promise.reject(`Failed to update document: ${error}`); 57,5: // } 58,5: // } 59,5: // | I41: 1 | J41: =D41 -> 2 | K41: Bravo!
A42: 7.3 Enum | B42: Le code utilise des enum lorsque c'est pertinent. | C42: 1 | D42: 2 | E42: Bravo! | F42: 1 | G42: =D42 -> 2 | H42: Bon travail! | I42: 1 | J42: =D42 -> 2 | K42: Bravo!
A43: 7.4 Classe et interface | B43: Le code n'utilise pas d'objets anonymes JS et priorise les classes et les interfaces. | C43: 0.75 | D43: 4 | E43: server/app/gateways/chat/chat.gateway.ts 23,16: return { isValid: word?.length > WORD_MIN_LENGTH }; | F43: 0.9 | G43: =D43 -> 4 | H43: client\src\app\interfaces\question.ts 5,14: choices: { text: string; isCorrect: boolean }[]; | I43: 1 | J43: =D43 -> 4 | K43: Bravo!
...

Sheet Fonctionnalités
A2: Grille de correction LOG2990
A4: Fonctionnalités
A6: Sprint 1
A7: Fonctionnalité | B7: Note | C7: Testé | D7: Poids | E7: Note finale | F7: Correcteur | G7: Commentaires
A8: Vue initiale | B8: 1 | C8: 1 | D8: 5 | E8: =B8*C8*D8 -> 5 | F8: MOD-AS
A9: Vue d'administration | B9: 0.1 | C9: 1 | D9: 20 | E9: =B9*C9*D9 -> 2 | F9: MOD-AS | G9: Plein de test game qui n'existent pas vraiment Erreur lors de l'importation Supprimer un jeu ne fonctionne pas Changer la visibilité instable Modification de jeu donne la même vue que création d'un jeu Modifier un jeu ne fonctionne pas Aucune rétroaction lors de la validation d'un json Deux boutons de visibilités
A10: Vue de création d'une partie | B10: 1 | C10: 1 | D10: 10 | E10: =B10*C10*D10 -> 10 | F10: MOD-AS
A11: Vue de jeu du joueur | B11: 0.75 | C11: 1 | D11: 20 | E11: =B11*C11*D11 -> 15 | F11: MOD-AS | G11: Impossible de choisir le choix par le clavier Compte à rebours ne fonctionne pas
A12: Création d'un jeu-questionnaire (QCM) | B12: 0.6 | C12: 1 | D12: 30 | E12: =B12*C12*D12 -> 18 | F12: MOD-AS | G12: Pas de rétroaction quand jeu créé Quand on crée une partie, un questionnaire est créé par question
A13: Tester le jeu | B13: 0.75 | C13: 0.75 | D13: 15 | E13: =B13*C13*D13 -> 8.4375 | F13: MOD-AS | G13: Impossible de passer d'une question à l'autre (on peut seulement jouer avec la première question) TestGamePageComponent pas testée
A14: Note finale pour le sprint | D14: =SUM(D8:D13) -> 100 | E14: =(SUM(E8:E13)+E16+E17)/D14 -> 0.534375
A15: Pénalités | B15: Note | D15: Poids | E15: Note finale | G15: Commentaires
A16: Crash | B16: 0.5 | D16: -10 | E16: =B16*D16 -> -5 | G16: Erreurs rouges dans la console + Erreurs bleues quand on lance les tests
A17: Erreur de build | D17: -15 | E17: =B17*D17 -> 0
A18: Sprint 2
A19: Fonctionnalité | B19: Note | C19: Testé | D19: Poids | E19: Note finale | F19: Correcteur | G19: Commentaires
A20: Joindre une partie | B20: 1 | C20: 1 | D20: 15 | E20: =B20*C20*D20 -> 15 | F20: MOD-AS | G20: Ok
A21: Vue d'attente des joueurs | B21: 0.9 | C21: 1 | D21: 20 | E21: =B21*C21*D21 -> 18 | F21: MOD-AS | G21: On peut bannir plusieurs fois le même joueur
A22: Vue de jeu de l'organisateur | B22: 1 | C22: 1 | D22: 20 | E22: =B22*C22*D22 -> 20 | F22: MOD-AS | G22: Ok
A23: Partie de jeu-questionnaire (QCM) | B23: 0.8 | C23: 1 | D23: 30 | E23: =B23*C23*D23 -> 24 | F23: MOD-AS | G23: Abandonner avec le fureteur ne fonctionne pas
A24: Clavardage | B24: 1 | C24: 1 | D24: 15 | E24: =B24*C24*D24 -> 15 | F24: MOD-AS | G24: Ok
A25: Note finale pour le sprint | D25: =SUM(D20:D24) -> 100 | E25: =(SUM(E20:E24) + E27+E28+E29)/D25 -> 0.82
A26: Pénalités | B26: Note | D26: Poids | E26: Note finale | G26: Commentaires
A27: Crash | B27: 1 | D27: -10 | E27: =B27*D27 -> -10 | G27: Les tests du client ne devrait pas demander le lancement du serveur
A28: Erreur de build / déploiement erroné | B28: 0 | D28: -15 | E28: =B28*D28 -> 0
A29: Anciennes fonctionnalités brisées | B29: 0 | D29: -5 | E29: =B29*D29 -> 0
A30: Sprint 3
A31: Fonctionnalité | B31: Note | C31: Testé | D31: Poids | E31: Note finale | F31: Correcteur | G31: Commentaires
A32: Création d'un jeu-questionnaire (QRL) | B32: 0.8 | C32: 1 | D32: 10 | E32: =B32*C32*D32 -> 8 | F32: MOD-AS | G32: Points obtenus accepter hors intervalle [10,100]
A33: Partie de jeu-questionnaire (QRL) | B33: 1 | C33: 1 | D33: 25 | E33: =B33*C33*D33 -> 25 | F33: MOD-AS | G33: Ok
A34: Compte à rebours intéractif | B34: 1 | C34: 1 | D34: 15 | E34: =B34*C34*D34 -> 15 | F34: MOD-AS | G34: Ok
A35: Liste des joueurs intéractive | B35: 1 | C35: 1 | D35: 20 | E35: =B35*C35*D35 -> 20 | F35: MOD-AS | G35: Ok
A36: Vue des résultats | B36: 0.9 | C36: 1 | D36: 15 | E36: =B36*C36*D36 -> 13.5 | F36: MOD-AS | G36: Vous avez inverser ordre croissant decroissant
A37: Historique | B37: 1 | C37: 1 | D37: 15 | E37: =B37*C37*D37 -> 15 | F37: MOD-AS | G37: Ok
A38: Note finale pour le sprint | D38: =SUM(D32:D37) -> 100 | E38: =(SUM(E32:E37) +E40+E41+E42)/D38 -> 0.965
A39: Pénalités | B39: Note | D39: Poids | E39: Note finale | G39: Commentaires
A40: Crash | B40: 0 | D40: -10 | E40: =B40*D40 -> 0
A41: Erreur de build / déploiement erroné | B41: 0 | D41: -15 | E41: =B41*D41 -> 0
A42: Anciennes fonctionnalités brisées | B42: 0 | D42: -5 | E42: =B42*D42 -> 0

Sheet Documents
A1: Document d'Architecture | D1: Protocole de communication
B2: Commentaires | E2: Commentaires
A3: Historique des révisions | D3: Historique des révisions
A4: 1 Introduction /1 | B4: 1 | D4: 1 Introduction /1 | E4: 1
B5: Correct | E5: Bien
A6: 2 Vue des cas d'utilisation /8 | B6: 5 | D6: 2 Communication client-serveur /7 | E6: 5
B7: Figure 2: Fausses liens entre les acteurs et les cas d'utilisations. Ne doivent pas être des flêches. Figure 3: Il faut avoir un seul acteur. Les relations de généralisations ne sont pas convenables dans ce cas. Il faut utiliser que des verbes d'action. Les lignes entre les acteurs et les cas d'utilisations ne doivent pas etre des flêches. Erreurs généraux: Les types de fleches utilisés ne sont pas bons. (fausses relations entres les cas d'utilisations). Il doit avoir toujours des verbes d'action. | E7: La justification de l'utilisation des websockets n'est pas claire. On les utilise à cause de leur caractère bidirectionnel
A8: 3 Vue des processus /8 | B8: 7 | D8: 3 Description des paquets /12 | E8: 5
B9: Figure 7: Une action d'acteur doit déclancher le processus. Pas de nom de diagramme dans le grand bloc. Plusieurs scénarios différents qui doivent etre séparés par des blocs. ChangeVisibility ne fait pas de changement dans le client? Acteur n'a pas un temps de vie. Temps de vies doivent dépendre des actions et des scénarios et ne sont pas toujours infinies. ِCeci s'applique pour toutes les autres figures. | E9: La route "Importer un fichier .JSON." n'est pas très claire. Elle requiert un fichier ou une interface ? Expliquer les cas dans lesquels le serveur retourne une erreur Ce n'est pas très utile de specifier les "Événements Potentiellement déclenchés" si vous n'expliquez pas les circonstances Plusieurs /GET sur la même route La case donnée n'est pas claire. Elle ne spécifie pas de données mais plus tôt des types
A10: 4 Vue de déploiement /3 | B10: 0.25
B11: Auncun déploiement n'est fait sur le personnage client. Il ne devrait pas faire partie de ce diagramme Vous devez bien faire la distinction entre le serveur statique (GitLab Pages) et le serveur dynamique (hébergé sur AWS). L'un n'est pas une cache de l'autre Vous n'avez pas besoin de mentionner les composants de bas niveaux comme les services. Idéalement limitez vous au détail concernant à la machine, le serveur/service déployé, l'environnement d'exécution (si connu et application) et les différentes interactions entre ces services
A12: Forme /1 | B12: 0.75 | D12: Forme /1 | E12: 0.75
B13: Les titres et les légendes doivent se trouver en bas de l'image La table de matière doit être sur une page séparée | E13: Aucun titre de tableau
A14: FOND (90%) | B14: =SUM(B4,B6,B8,B10) -> 13.25 | D14: FOND (90%) | E14: =SUM(E4,E6,E8) -> 11
A15: FORME (10%) | B15: =B12 -> 0.75 | D15: FORME (10%) | E15: =E12 -> 0.75
A16: NOTE | B16: =B14/20*0.9+B15*0.1 -> 0.67125 | D16: NOTE | E16: =E14/20*0.9+E15*0.1 -> 0.57
